INFO2017-09-21 04:48:36,414[basehttp.pylog_message124] [pid 3268, Thread 6140]:
WARNING2017-09-21 04:48:36,624[base.pyget_response152] [pid 3268, Thread 5048]:
WARNING2017-09-21 04:48:36,625[basehttp.pylog_message124] [pid 3268, Thread 5048]:
INFO2017-09-21 04:48:38,280[basehttp.pylog_message124] [pid 3268, Thread 2036]:
WARNING2017-09-21 04:48:38,302[basehttp.pylog_message124] [pid 3268, Thread 4232]:
WARNING2017-09-21 04:48:38,421[basehttp.pylog_message124] [pid 3268, Thread 4336]:
INFO2017-09-21 04:56:51,462[basehttp.pylog_message124] [pid 6992, Thread 2208]:
INFO2017-09-21 04:59:21,357[basehttp.pylog_message124] [pid 5216, Thread 6100]:
INFO2017-09-21 05:10:10,779[django.serverlog_message124] [pid 4608, Thread 2768]:
INFO2017-09-21 05:10:12,518[django.serverlog_message124] [pid 4608, Thread 6688]:
WARNING2017-09-21 05:10:12,528[django.serverlog_message124] [pid 4608, Thread 5840]:
WARNING2017-09-21 05:10:12,657[django.serverlog_message124] [pid 4608, Thread 3268]:
DEBUG2017-09-21 05:12:04,877[django.db.backendsexecute91] [pid 2924, Thread 6656]:
DEBUG2017-09-21 05:12:04,878[django.db.backendsexecute91] [pid 2924, Thread 6656]:
DEBUG2017-09-21 05:12:05,028[django.db.backendsexecute91] [pid 2924, Thread 6656]:
DEBUG2017-09-21 05:12:05,030[django.db.backendsexecute91] [pid 2924, Thread 6656]:
DEBUG2017-09-21 05:12:08,915[django.db.backendsexecute91] [pid 2924, Thread 4272]:
DEBUG2017-09-21 05:12:08,915[django.db.backendsexecute91] [pid 2924, Thread 4272]:
INFO2017-09-21 05:12:08,924[django.serverlog_message124] [pid 2924, Thread 4272]:
DEBUG2017-09-21 05:12:28,689[django.db.backendsexecute91] [pid 2924, Thread 6332]:
DEBUG2017-09-21 05:12:28,690[django.db.backendsexecute91] [pid 2924, Thread 6332]:
DEBUG2017-09-21 05:12:28,699[django.template_resolve_lookup925] [pid 2924, Thread 6332]:
Traceback (most recent call last):
  File "C:\Users\admin\AppData\Local\Programs\Python\Python36-32\lib\site-packages\django\template\base.py", line 882, in _resolve_lookup
    current = current[bit]
  File "C:\Users\admin\AppData\Local\Programs\Python\Python36-32\lib\site-packages\django\template\context.py", line 87, in __getitem__
    raise KeyError(key)
KeyError: 'row1'

During handling of the above exception, another exception occurred:

Traceback (most recent call last):
  File "C:\Users\admin\AppData\Local\Programs\Python\Python36-32\lib\site-packages\django\template\base.py", line 888, in _resolve_lookup
    if isinstance(current, BaseContext) and getattr(type(current), bit):
AttributeError: type object 'RequestContext' has no attribute 'row1'

During handling of the above exception, another exception occurred:

Traceback (most recent call last):
  File "C:\Users\admin\AppData\Local\Programs\Python\Python36-32\lib\site-packages\django\template\base.py", line 896, in _resolve_lookup
    current = current[int(bit)]
ValueError: invalid literal for int() with base 10: 'row1'

During handling of the above exception, another exception occurred:

Traceback (most recent call last):
  File "C:\Users\admin\AppData\Local\Programs\Python\Python36-32\lib\site-packages\django\template\base.py", line 903, in _resolve_lookup
    (bit, current))  # missing attribute
django.template.base.VariableDoesNotExist: Failed lookup for key [row1] in '[{\'True\': True, \'False\': False, \'None\': None}, {\'csrf_token\': <SimpleLazyObject: \'6u9a8hSylr0v1dpwvmAxdQSM5C96acf7Ksoyxb8Jm0TtF0bcFOzYXAYcKqfiH7NB\'>, \'request\': <WSGIRequest: GET \'/agent/add/\'>, \'user\': <SimpleLazyObject: <function AuthenticationMiddleware.process_request.<locals>.<lambda> at 0x04374A08>>, \'perms\': <django.contrib.auth.context_processors.PermWrapper object at 0x04C3DFD0>, \'messages\': <django.contrib.messages.storage.fallback.FallbackStorage object at 0x04C0BDF0>, \'DEFAULT_MESSAGE_LEVELS\': {\'DEBUG\': 10, \'INFO\': 20, \'SUCCESS\': 25, \'WARNING\': 30, \'ERROR\': 40}}, {}, {\'form\': <AgentForm bound=False, valid=False, fields=(first_name;last_name;age;education;company_name;specialization;experience;agent_notes;mobile_number;phone_number;email_id;media_name;property_type)>, \'view\': <Tagent4.views.AgentAddrLocArefCreate object at 0x04C0B150>, \'location\': <django.forms.formsets.LocationFormFormSet object at 0x04C0B3B0>, \'address\': <django.forms.formsets.AddressFormFormSet object at 0x04C0BC30>, \'agentreferal\': <django.forms.formsets.AgentReferalFormFormSet object at 0x04C0B350>}, {\'block\': <Block Node: content. Contents: [<TextNode: \'\\n    <h2>Agent Details</h\'>, <django.template.defaulttags.CsrfTokenNode object at 0x04C54190>, <TextNode: \'\\n            \'>, <Variable Node: form.as_p>, <TextNode: \'\\n\\n         <table class="\'>, <Variable Node: address.management_form>, <TextNode: \'\\n                \'>, <For Node: for form in address.forms, tail_len: 7>, <TextNode: \'\\n            </table>\\n\\n\\n\\n\'>, <Variable Node: location.management_form>, <TextNode: \'\\n                \'>, <For Node: for form in location.forms, tail_len: 7>, <TextNode: \'\\n            </table>\\n\\n\\n\\n\'>, <Variable Node: agentreferal.management_form>, <TextNode: \'\\n                \'>, <For Node: for form in agentreferal.forms, tail_len: 7>, <TextNode: \'\\n            </table>\\n\\n\\n\\n\'>, <django.template.defaulttags.URLNode object at 0x04C59570>, <TextNode: \'">back to the list</a>\\n  \'>, <django.templatetags.static.StaticNode object at 0x04C59A10>, <TextNode: \'"></script>\\n    <script t\'>]>}, {\'forloop\': {\'parentloop\': {}, \'counter0\': 0, \'counter\': 1, \'revcounter\': 1, \'revcounter0\': 0, \'first\': True, \'last\': True}, \'form\': <AddressForm bound=False, valid=Unknown, fields=(agent;address1;address2;city;state;landmark;pincode;address_id;DELETE)>}]'
DEBUG2017-09-21 05:12:28,778[django.template_resolve_lookup925] [pid 2924, Thread 6332]:
Traceback (most recent call last):
  File "C:\Users\admin\AppData\Local\Programs\Python\Python36-32\lib\site-packages\django\template\base.py", line 882, in _resolve_lookup
    current = current[bit]
KeyError: 'second'

During handling of the above exception, another exception occurred:

Traceback (most recent call last):
  File "C:\Users\admin\AppData\Local\Programs\Python\Python36-32\lib\site-packages\django\template\base.py", line 890, in _resolve_lookup
    current = getattr(current, bit)
AttributeError: 'dict' object has no attribute 'second'

During handling of the above exception, another exception occurred:

Traceback (most recent call last):
  File "C:\Users\admin\AppData\Local\Programs\Python\Python36-32\lib\site-packages\django\template\base.py", line 896, in _resolve_lookup
    current = current[int(bit)]
ValueError: invalid literal for int() with base 10: 'second'

During handling of the above exception, another exception occurred:

Traceback (most recent call last):
  File "C:\Users\admin\AppData\Local\Programs\Python\Python36-32\lib\site-packages\django\template\base.py", line 903, in _resolve_lookup
    (bit, current))  # missing attribute
django.template.base.VariableDoesNotExist: Failed lookup for key [second] in "{'parentloop': {}, 'counter0': 0, 'counter': 1, 'revcounter': 1, 'revcounter0': 0, 'first': True, 'last': True}"
DEBUG2017-09-21 05:12:28,779[django.template_resolve_lookup925] [pid 2924, Thread 6332]:
Traceback (most recent call last):
  File "C:\Users\admin\AppData\Local\Programs\Python\Python36-32\lib\site-packages\django\template\base.py", line 882, in _resolve_lookup
    current = current[bit]
  File "C:\Users\admin\AppData\Local\Programs\Python\Python36-32\lib\site-packages\django\template\context.py", line 87, in __getitem__
    raise KeyError(key)
KeyError: 'row1'

During handling of the above exception, another exception occurred:

Traceback (most recent call last):
  File "C:\Users\admin\AppData\Local\Programs\Python\Python36-32\lib\site-packages\django\template\base.py", line 888, in _resolve_lookup
    if isinstance(current, BaseContext) and getattr(type(current), bit):
AttributeError: type object 'RequestContext' has no attribute 'row1'

During handling of the above exception, another exception occurred:

Traceback (most recent call last):
  File "C:\Users\admin\AppData\Local\Programs\Python\Python36-32\lib\site-packages\django\template\base.py", line 896, in _resolve_lookup
    current = current[int(bit)]
ValueError: invalid literal for int() with base 10: 'row1'

During handling of the above exception, another exception occurred:

Traceback (most recent call last):
  File "C:\Users\admin\AppData\Local\Programs\Python\Python36-32\lib\site-packages\django\template\base.py", line 903, in _resolve_lookup
    (bit, current))  # missing attribute
django.template.base.VariableDoesNotExist: Failed lookup for key [row1] in '[{\'True\': True, \'False\': False, \'None\': None}, {\'csrf_token\': <SimpleLazyObject: \'6u9a8hSylr0v1dpwvmAxdQSM5C96acf7Ksoyxb8Jm0TtF0bcFOzYXAYcKqfiH7NB\'>, \'request\': <WSGIRequest: GET \'/agent/add/\'>, \'user\': <SimpleLazyObject: <function AuthenticationMiddleware.process_request.<locals>.<lambda> at 0x04374A08>>, \'perms\': <django.contrib.auth.context_processors.PermWrapper object at 0x04C3DFD0>, \'messages\': <django.contrib.messages.storage.fallback.FallbackStorage object at 0x04C0BDF0>, \'DEFAULT_MESSAGE_LEVELS\': {\'DEBUG\': 10, \'INFO\': 20, \'SUCCESS\': 25, \'WARNING\': 30, \'ERROR\': 40}}, {}, {\'form\': <AgentForm bound=False, valid=False, fields=(first_name;last_name;age;education;company_name;specialization;experience;agent_notes;mobile_number;phone_number;email_id;media_name;property_type)>, \'view\': <Tagent4.views.AgentAddrLocArefCreate object at 0x04C0B150>, \'location\': <django.forms.formsets.LocationFormFormSet object at 0x04C0B3B0>, \'address\': <django.forms.formsets.AddressFormFormSet object at 0x04C0BC30>, \'agentreferal\': <django.forms.formsets.AgentReferalFormFormSet object at 0x04C0B350>}, {\'block\': <Block Node: content. Contents: [<TextNode: \'\\n    <h2>Agent Details</h\'>, <django.template.defaulttags.CsrfTokenNode object at 0x04C54190>, <TextNode: \'\\n            \'>, <Variable Node: form.as_p>, <TextNode: \'\\n\\n         <table class="\'>, <Variable Node: address.management_form>, <TextNode: \'\\n                \'>, <For Node: for form in address.forms, tail_len: 7>, <TextNode: \'\\n            </table>\\n\\n\\n\\n\'>, <Variable Node: location.management_form>, <TextNode: \'\\n                \'>, <For Node: for form in location.forms, tail_len: 7>, <TextNode: \'\\n            </table>\\n\\n\\n\\n\'>, <Variable Node: agentreferal.management_form>, <TextNode: \'\\n                \'>, <For Node: for form in agentreferal.forms, tail_len: 7>, <TextNode: \'\\n            </table>\\n\\n\\n\\n\'>, <django.template.defaulttags.URLNode object at 0x04C59570>, <TextNode: \'">back to the list</a>\\n  \'>, <django.templatetags.static.StaticNode object at 0x04C59A10>, <TextNode: \'"></script>\\n    <script t\'>]>}, {\'forloop\': {\'parentloop\': {}, \'counter0\': 0, \'counter\': 1, \'revcounter\': 1, \'revcounter0\': 0, \'first\': True, \'last\': True}, \'form\': <LocationForm bound=False, valid=Unknown, fields=(agent;city;state;location_id;DELETE)>}]'
DEBUG2017-09-21 05:12:28,794[django.template_resolve_lookup925] [pid 2924, Thread 6332]:
Traceback (most recent call last):
  File "C:\Users\admin\AppData\Local\Programs\Python\Python36-32\lib\site-packages\django\template\base.py", line 882, in _resolve_lookup
    current = current[bit]
KeyError: 'second'

During handling of the above exception, another exception occurred:

Traceback (most recent call last):
  File "C:\Users\admin\AppData\Local\Programs\Python\Python36-32\lib\site-packages\django\template\base.py", line 890, in _resolve_lookup
    current = getattr(current, bit)
AttributeError: 'dict' object has no attribute 'second'

During handling of the above exception, another exception occurred:

Traceback (most recent call last):
  File "C:\Users\admin\AppData\Local\Programs\Python\Python36-32\lib\site-packages\django\template\base.py", line 896, in _resolve_lookup
    current = current[int(bit)]
ValueError: invalid literal for int() with base 10: 'second'

During handling of the above exception, another exception occurred:

Traceback (most recent call last):
  File "C:\Users\admin\AppData\Local\Programs\Python\Python36-32\lib\site-packages\django\template\base.py", line 903, in _resolve_lookup
    (bit, current))  # missing attribute
django.template.base.VariableDoesNotExist: Failed lookup for key [second] in "{'parentloop': {}, 'counter0': 0, 'counter': 1, 'revcounter': 1, 'revcounter0': 0, 'first': True, 'last': True}"
DEBUG2017-09-21 05:12:28,794[django.template_resolve_lookup925] [pid 2924, Thread 6332]:
Traceback (most recent call last):
  File "C:\Users\admin\AppData\Local\Programs\Python\Python36-32\lib\site-packages\django\template\base.py", line 882, in _resolve_lookup
    current = current[bit]
  File "C:\Users\admin\AppData\Local\Programs\Python\Python36-32\lib\site-packages\django\template\context.py", line 87, in __getitem__
    raise KeyError(key)
KeyError: 'row1'

During handling of the above exception, another exception occurred:

Traceback (most recent call last):
  File "C:\Users\admin\AppData\Local\Programs\Python\Python36-32\lib\site-packages\django\template\base.py", line 888, in _resolve_lookup
    if isinstance(current, BaseContext) and getattr(type(current), bit):
AttributeError: type object 'RequestContext' has no attribute 'row1'

During handling of the above exception, another exception occurred:

Traceback (most recent call last):
  File "C:\Users\admin\AppData\Local\Programs\Python\Python36-32\lib\site-packages\django\template\base.py", line 896, in _resolve_lookup
    current = current[int(bit)]
ValueError: invalid literal for int() with base 10: 'row1'

During handling of the above exception, another exception occurred:

Traceback (most recent call last):
  File "C:\Users\admin\AppData\Local\Programs\Python\Python36-32\lib\site-packages\django\template\base.py", line 903, in _resolve_lookup
    (bit, current))  # missing attribute
django.template.base.VariableDoesNotExist: Failed lookup for key [row1] in '[{\'True\': True, \'False\': False, \'None\': None}, {\'csrf_token\': <SimpleLazyObject: \'6u9a8hSylr0v1dpwvmAxdQSM5C96acf7Ksoyxb8Jm0TtF0bcFOzYXAYcKqfiH7NB\'>, \'request\': <WSGIRequest: GET \'/agent/add/\'>, \'user\': <SimpleLazyObject: <function AuthenticationMiddleware.process_request.<locals>.<lambda> at 0x04374A08>>, \'perms\': <django.contrib.auth.context_processors.PermWrapper object at 0x04C3DFD0>, \'messages\': <django.contrib.messages.storage.fallback.FallbackStorage object at 0x04C0BDF0>, \'DEFAULT_MESSAGE_LEVELS\': {\'DEBUG\': 10, \'INFO\': 20, \'SUCCESS\': 25, \'WARNING\': 30, \'ERROR\': 40}}, {}, {\'form\': <AgentForm bound=False, valid=False, fields=(first_name;last_name;age;education;company_name;specialization;experience;agent_notes;mobile_number;phone_number;email_id;media_name;property_type)>, \'view\': <Tagent4.views.AgentAddrLocArefCreate object at 0x04C0B150>, \'location\': <django.forms.formsets.LocationFormFormSet object at 0x04C0B3B0>, \'address\': <django.forms.formsets.AddressFormFormSet object at 0x04C0BC30>, \'agentreferal\': <django.forms.formsets.AgentReferalFormFormSet object at 0x04C0B350>}, {\'block\': <Block Node: content. Contents: [<TextNode: \'\\n    <h2>Agent Details</h\'>, <django.template.defaulttags.CsrfTokenNode object at 0x04C54190>, <TextNode: \'\\n            \'>, <Variable Node: form.as_p>, <TextNode: \'\\n\\n         <table class="\'>, <Variable Node: address.management_form>, <TextNode: \'\\n                \'>, <For Node: for form in address.forms, tail_len: 7>, <TextNode: \'\\n            </table>\\n\\n\\n\\n\'>, <Variable Node: location.management_form>, <TextNode: \'\\n                \'>, <For Node: for form in location.forms, tail_len: 7>, <TextNode: \'\\n            </table>\\n\\n\\n\\n\'>, <Variable Node: agentreferal.management_form>, <TextNode: \'\\n                \'>, <For Node: for form in agentreferal.forms, tail_len: 7>, <TextNode: \'\\n            </table>\\n\\n\\n\\n\'>, <django.template.defaulttags.URLNode object at 0x04C59570>, <TextNode: \'">back to the list</a>\\n  \'>, <django.templatetags.static.StaticNode object at 0x04C59A10>, <TextNode: \'"></script>\\n    <script t\'>]>}, {\'forloop\': {\'parentloop\': {}, \'counter0\': 0, \'counter\': 1, \'revcounter\': 1, \'revcounter0\': 0, \'first\': True, \'last\': True}, \'form\': <AgentReferalForm bound=False, valid=Unknown, fields=(agent;name;verified;referal_id;DELETE)>}]'
INFO2017-09-21 05:12:28,805[django.serverlog_message124] [pid 2924, Thread 6332]:
WARNING2017-09-21 05:12:28,815[django.serverlog_message124] [pid 2924, Thread 2000]:
WARNING2017-09-21 05:12:28,912[django.serverlog_message124] [pid 2924, Thread 4564]:
INFO2017-09-21 05:16:46,994[Tagent4.viewsAgentCreate50] [pid 3748, Thread 1272]:
INFO2017-09-21 05:18:05,261[Tagent4.viewsAgentCreate50] [pid 7008, Thread 384]:
INFO2017-09-21 05:18:05,262[Tagent4.viewsAgentAddrLocArefCreate56] [pid 7008, Thread 384]:
INFO2017-09-21 05:22:19,577[Tagent4.viewsAgentCreate50] [pid 1032, Thread 3888]:
INFO2017-09-21 05:22:19,578[Tagent4.viewsAgentAddrLocArefCreate56] [pid 1032, Thread 3888]:
INFO2017-09-21 05:22:19,578[Tagent4.viewsAgentUpdate94] [pid 1032, Thread 3888]:
INFO2017-09-21 05:22:19,578[Tagent4.viewsAgentAddrLocArefUpdate100] [pid 1032, Thread 3888]:
INFO2017-09-21 05:22:22,919[Tagent4.viewsget_context_data59] [pid 1032, Thread 368]:
INFO2017-09-21 05:23:51,406[Tagent4.viewsAgentAddrLocArefCreate56] [pid 5752, Thread 5500]:
INFO2017-09-21 05:23:51,406[Tagent4.viewsAgentUpdate94] [pid 5752, Thread 5500]:
INFO2017-09-21 05:23:51,406[Tagent4.viewsAgentAddrLocArefUpdate100] [pid 5752, Thread 5500]:
INFO2017-09-21 05:24:31,352[Tagent4.viewsget_context_data59] [pid 5752, Thread 4192]:
INFO2017-09-21 05:25:12,033[Tagent4.viewsAgentCreate50] [pid 2832, Thread 5584]:
INFO2017-09-21 05:25:12,034[Tagent4.viewsAgentAddrLocArefCreate56] [pid 2832, Thread 5584]:
INFO2017-09-21 05:25:12,034[Tagent4.viewsAgentUpdate94] [pid 2832, Thread 5584]:
INFO2017-09-21 05:25:12,034[Tagent4.viewsAgentAddrLocArefUpdate100] [pid 2832, Thread 5584]:
INFO2017-09-21 05:25:47,024[Tagent4.viewsAgentCreate50] [pid 4508, Thread 3048]:
INFO2017-09-21 05:25:47,025[Tagent4.viewsAgentAddrLocArefCreate56] [pid 4508, Thread 3048]:
INFO2017-09-21 05:25:47,025[Tagent4.viewsAgentUpdate94] [pid 4508, Thread 3048]:
INFO2017-09-21 05:25:47,025[Tagent4.viewsAgentAddrLocArefUpdate100] [pid 4508, Thread 3048]:
INFO2017-09-21 05:25:49,896[Tagent4.viewsget_context_data59] [pid 4508, Thread 6692]:
INFO2017-09-21 05:26:41,308[Tagent4.viewsAgentCreate50] [pid 3692, Thread 6644]:
INFO2017-09-21 05:26:41,309[Tagent4.viewsAgentAddrLocArefCreate56] [pid 3692, Thread 6644]:
INFO2017-09-21 05:26:41,309[Tagent4.viewsAgentUpdate94] [pid 3692, Thread 6644]:
INFO2017-09-21 05:26:41,309[Tagent4.viewsAgentAddrLocArefUpdate100] [pid 3692, Thread 6644]:
INFO2017-09-21 05:26:52,229[Tagent4.viewsAgentCreate50] [pid 3736, Thread 4428]:
INFO2017-09-21 05:26:52,229[Tagent4.viewsAgentAddrLocArefCreate56] [pid 3736, Thread 4428]:
INFO2017-09-21 05:26:52,229[Tagent4.viewsAgentUpdate94] [pid 3736, Thread 4428]:
INFO2017-09-21 05:26:52,229[Tagent4.viewsAgentAddrLocArefUpdate100] [pid 3736, Thread 4428]:
DEBUG2017-09-21 05:28:08,277[Tagent4.viewsAgentCreate50] [pid 4572, Thread 2268]:
INFO2017-09-21 05:28:08,278[Tagent4.viewsAgentAddrLocArefCreate56] [pid 4572, Thread 2268]:
DEBUG2017-09-21 05:28:08,278[Tagent4.viewsAgentUpdate94] [pid 4572, Thread 2268]:
INFO2017-09-21 05:28:08,278[Tagent4.viewsAgentAddrLocArefUpdate100] [pid 4572, Thread 2268]:
DEBUG2017-09-21 05:32:36,943[Tagent4.viewsAgentCreate50] [pid 3876, Thread 992]:
INFO2017-09-21 05:32:36,944[Tagent4.viewsAgentAddrLocArefCreate56] [pid 3876, Thread 992]:
DEBUG2017-09-21 05:32:36,944[Tagent4.viewsAgentUpdate94] [pid 3876, Thread 992]:
INFO2017-09-21 05:32:36,944[Tagent4.viewsAgentAddrLocArefUpdate100] [pid 3876, Thread 992]:
DEBUG2017-09-21 05:33:35,859[Tagent4.viewsAgentCreate50] [pid 5960, Thread 3480]:
ERROR2017-09-21 05:33:35,859[Tagent4.viewsAgentAddrLocArefCreate56] [pid 5960, Thread 3480]:
DEBUG2017-09-21 05:33:35,859[Tagent4.viewsAgentUpdate94] [pid 5960, Thread 3480]:
INFO2017-09-21 05:33:35,859[Tagent4.viewsAgentAddrLocArefUpdate100] [pid 5960, Thread 3480]:
DEBUG2017-09-21 05:34:22,547[Tagent4.viewsAgentCreate50] [pid 6436, Thread 4944]:
INFO2017-09-21 05:34:22,547[Tagent4.viewsAgentAddrLocArefCreate56] [pid 6436, Thread 4944]:
DEBUG2017-09-21 05:34:22,547[Tagent4.viewsAgentUpdate94] [pid 6436, Thread 4944]:
INFO2017-09-21 05:34:22,547[Tagent4.viewsAgentAddrLocArefUpdate100] [pid 6436, Thread 4944]:
DEBUG2017-09-21 05:39:44,780[Tagent4.viewsAgentCreate50] [pid 6936, Thread 6184]:
INFO2017-09-21 05:39:44,780[Tagent4.viewsAgentAddrLocArefCreate56] [pid 6936, Thread 6184]:
DEBUG2017-09-21 05:39:44,780[Tagent4.viewsAgentUpdate94] [pid 6936, Thread 6184]:
INFO2017-09-21 05:39:44,780[Tagent4.viewsAgentAddrLocArefUpdate100] [pid 6936, Thread 6184]:
DEBUG2017-09-21 05:40:33,300[Tagent4.viewsAgentCreate50] [pid 4584, Thread 1708]:
INFO2017-09-21 05:40:33,301[Tagent4.viewsAgentAddrLocArefCreate56] [pid 4584, Thread 1708]:
DEBUG2017-09-21 05:40:33,301[Tagent4.viewsAgentUpdate94] [pid 4584, Thread 1708]:
INFO2017-09-21 05:40:33,301[Tagent4.viewsAgentAddrLocArefUpdate100] [pid 4584, Thread 1708]:
INFO2017-09-21 05:51:26,165[Tagent4.views<module>11] [pid 5180, Thread 4248]:
DEBUG2017-09-21 05:51:26,166[Tagent4.viewsAgentCreate51] [pid 5180, Thread 4248]:
INFO2017-09-21 05:51:26,166[Tagent4.viewsAgentAddrLocArefCreate57] [pid 5180, Thread 4248]:
DEBUG2017-09-21 05:51:26,166[Tagent4.viewsAgentUpdate95] [pid 5180, Thread 4248]:
INFO2017-09-21 05:51:26,166[Tagent4.viewsAgentAddrLocArefUpdate101] [pid 5180, Thread 4248]:
INFO2017-09-21 06:05:29,714[Tagent4.views<module>11] [pid 3336, Thread 5656]:
DEBUG2017-09-21 06:05:29,715[Tagent4.viewsAgentCreate56] [pid 3336, Thread 5656]:
INFO2017-09-21 06:05:29,715[Tagent4.viewsAgentAddrLocArefCreate62] [pid 3336, Thread 5656]:
DEBUG2017-09-21 06:05:29,716[Tagent4.viewsAgentUpdate100] [pid 3336, Thread 5656]:
INFO2017-09-21 06:05:29,716[Tagent4.viewsAgentAddrLocArefUpdate106] [pid 3336, Thread 5656]:
INFO2017-09-21 06:08:50,807[Tagent4.views<module>11] [pid 5400, Thread 652]:
DEBUG2017-09-21 06:08:50,807[Tagent4.viewsAgentCreate50] [pid 5400, Thread 652]:
INFO2017-09-21 06:08:50,807[Tagent4.viewsAgentAddrLocArefCreate56] [pid 5400, Thread 652]:
DEBUG2017-09-21 06:08:50,807[Tagent4.viewsAgentUpdate94] [pid 5400, Thread 652]:
INFO2017-09-21 06:08:50,807[Tagent4.viewsAgentAddrLocArefUpdate100] [pid 5400, Thread 652]:
INFO2017-09-21 06:45:05,881[Tagent4.views<module>11] [pid 3572, Thread 2900]:
DEBUG2017-09-21 06:45:05,882[Tagent4.viewsAgentCreate50] [pid 3572, Thread 2900]:
INFO2017-09-21 06:45:05,882[Tagent4.viewsAgentAddrLocArefCreate56] [pid 3572, Thread 2900]:
DEBUG2017-09-21 06:45:05,883[Tagent4.viewsAgentUpdate94] [pid 3572, Thread 2900]:
INFO2017-09-21 06:45:05,883[Tagent4.viewsAgentAddrLocArefUpdate100] [pid 3572, Thread 2900]:
INFO2017-09-21 06:47:30,576[Tagent4.views<module>11] [pid 5800, Thread 3032]:
DEBUG2017-09-21 06:47:30,576[Tagent4.viewsAgentCreate50] [pid 5800, Thread 3032]:
INFO2017-09-21 06:47:30,576[Tagent4.viewsAgentAddrLocArefCreate56] [pid 5800, Thread 3032]:
DEBUG2017-09-21 06:47:30,576[Tagent4.viewsAgentUpdate94] [pid 5800, Thread 3032]:
INFO2017-09-21 06:47:30,576[Tagent4.viewsAgentAddrLocArefUpdate100] [pid 5800, Thread 3032]:
